<?xml version="1.0" encoding="utf-8"?>
<!-- =================================================================================== -->
<!-- |    This document was autogenerated by xacro from 3WD_Omnibot.urdf.xacro         | -->
<!-- |    EDITING THIS FILE BY HAND IS NOT RECOMMENDED                                 | -->
<!-- =================================================================================== -->
<robot name="macroed">
  <material name="dark_grey">
    <color rgba="0 0 0.8 1"/>
  </material>
  <material name="grey">
    <color rgba="0.1 0.1 0.1 1"/>
  </material>
  <material name="yellow">
    <color rgba="0.8 0.8 0.2 1"/>
  </material>
  <link name="base_link">
    <visual>
      <geometry>
        <mesh filename="package://nexus_base_ros/meshes/omnibot_body.dae"/>
      </geometry>
      <material name="yellow"/>
    </visual>
    <collision>
      <geometry>
        <cylinder length="0.115" radius="0.15"/>
      </geometry>
    </collision>
  </link>
  <link name="left_wheel_link">
    <visual>
      <origin rpy="1.57079632679 0 0"/>
      <geometry>
        <mesh filename="package://nexus_base_ros/meshes/mecanum_wheel.dae"/>
      </geometry>
      <material name="grey"/>
    </visual>
    <collision>
      <origin rpy="1.57079632679 0 0" xyz="0 0 0"/>
      <geometry>
        <cylinder length="0.1" radius="0.02"/>
      </geometry>
    </collision>
  </link>
  <joint name="left_wheel_joint" type="continuous">
    <axis rpy="0 0 0" xyz="0 1 0"/>
    <parent link="base_link"/>
    <child link="left_wheel_link"/>
    <origin rpy="0 0 -0.523598775598" xyz="0.0625 0.108253175473 0"/>
  </joint>
  <link name="back_wheel_link">
    <visual>
      <origin rpy="4.71238898038 0 0"/>
      <geometry>
        <mesh filename="package://nexus_base_ros/meshes/mecanum_wheel.dae"/>
      </geometry>
      <material name="grey"/>
    </visual>
    <collision>
      <origin rpy="1.57079632679 0 0" xyz="0 0 0"/>
      <geometry>
        <cylinder length="0.1" radius="0.02"/>
      </geometry>
    </collision>
  </link>
  <joint name="back_wheel_joint" type="continuous">
    <axis rpy="0 0 0" xyz="0 1 0"/>
    <parent link="base_link"/>
    <child link="back_wheel_link"/>
    <origin rpy="0 0 1.57079632679" xyz="-0.125 1.53080849893e-17 0"/>
  </joint>
  <link name="right_wheel_link">
    <visual>
      <origin rpy="1.57079632679 0 0"/>
      <geometry>
        <mesh filename="package://nexus_base_ros/meshes/mecanum_wheel.dae"/>
      </geometry>
      <material name="grey"/>
    </visual>
    <collision>
      <origin rpy="1.57079632679 0 0"/>
      <geometry>
        <cylinder length="0.1" radius="0.02"/>
      </geometry>
    </collision>
  </link>
  <joint name="right_wheel_joint" type="continuous">
    <axis rpy="0 0 0" xyz="0 1 0"/>
    <parent link="base_link"/>
    <child link="right_wheel_link"/>
    <origin rpy="0 0 3.66519142919" xyz="0.0625 -0.108253175473 0"/>
  </joint>
  <link name="lidar_link">
    <visual>
      <origin rpy="0 0 0" xyz="0 0 0"/>
      <geometry>
        <mesh filename="package://nexus_base_ros/meshes/RPLIDAR_A1M8.dae"/>
      </geometry>
      <material name="dark_grey"/>
    </visual>
  </link>
  <joint name="lidar_joint" type="fixed">
    <parent link="base_link"/>
    <child link="lidar_link"/>
    <origin rpy="0 0 0" xyz="0.095 0 0.115"/>
  </joint>
</robot>

